<?xml version="1.0" ?>
<robot name="ayspot_a1" xmlns:xacro="http://www.ros.org/wiki/xacro">

<xacro:include filename="$(find ayspot_a1_description)/urdf/materials.xacro" />
<xacro:include filename="$(find ayspot_a1_description)/urdf/ayspot_a1.trans" />
<xacro:include filename="$(find ayspot_a1_description)/urdf/ayspot_a1.gazebo" />
<link name="base_link">
  <inertial>
    <origin rpy="0 0 0" xyz="6.910961347512361e-05 -9.571412303731516e-05 0.012502598185418556"/>
    <mass value="7.464944385639965"/>
    <inertia ixx="0.062659" ixy="-2.2e-05" ixz="-0.0" iyy="0.056069" iyz="-9e-06" izz="0.096918"/>
  </inertial>
  <visual>
    <origin rpy="0 0 0" xyz="0 0 0"/>
    <geometry>
      <mesh filename="package://ayspot_a1_description/meshes/base_link.stl" scale="0.001 0.001 0.001"/>
    </geometry>
    <material name="silver"/>
  </visual>
  <collision>
    <origin rpy="0 0 0" xyz="0 0 0"/>
    <geometry>
      <mesh filename="package://ayspot_a1_description/meshes/base_link.stl" scale="0.001 0.001 0.001"/>
    </geometry>
  </collision>
</link>

<link name="RF_HIP_1">
  <inertial>
    <origin rpy="0 0 0" xyz="-0.023084404729865754 -0.006782862434818418 -5.5748818895053945e-08"/>
    <mass value="1.4355160412440473"/>
    <inertia ixx="0.001763" ixy="4.2e-05" ixz="-0.0" iyy="0.002514" iyz="0.0" izz="0.001514"/>
  </inertial>
  <visual>
    <origin rpy="0 0 0" xyz="-0.1808 0.065 0.0"/>
    <geometry>
      <mesh filename="package://ayspot_a1_description/meshes/RF_HIP_1.stl" scale="0.001 0.001 0.001"/>
    </geometry>
    <material name="silver"/>
  </visual>
  <collision>
    <origin rpy="0 0 0" xyz="-0.1808 0.065 0.0"/>
    <geometry>
      <mesh filename="package://ayspot_a1_description/meshes/RF_HIP_1.stl" scale="0.001 0.001 0.001"/>
    </geometry>
  </collision>
</link>

<link name="RF_THIGH_1">
  <inertial>
    <origin rpy="0 0 0" xyz="-3.1520768784126796e-05 0.029669373982814856 -0.0140945333441057"/>
    <mass value="1.9354245387114226"/>
    <inertia ixx="0.005386" ixy="-2e-06" ixz="-2e-06" iyy="0.005003" iyz="-0.000911" izz="0.002334"/>
  </inertial>
  <visual>
    <origin rpy="0 0 0" xyz="-0.1808 0.1588 0.0"/>
    <geometry>
      <mesh filename="package://ayspot_a1_description/meshes/RF_THIGH_1.stl" scale="0.001 0.001 0.001"/>
    </geometry>
    <material name="silver"/>
  </visual>
  <collision>
    <origin rpy="0 0 0" xyz="-0.1808 0.1588 0.0"/>
    <geometry>
      <mesh filename="package://ayspot_a1_description/meshes/RF_THIGH_1.stl" scale="0.001 0.001 0.001"/>
    </geometry>
  </collision>
</link>

<link name="RF_SHANK_1">
  <inertial>
    <origin rpy="0 0 0" xyz="0.0063162283936911146 -2.2250600217876837e-07 -0.06808977329384383"/>
    <mass value="0.5487464783038579"/>
    <inertia ixx="0.002626" ixy="-0.0" ixz="3.2e-05" iyy="0.002673" iyz="0.0" izz="9.8e-05"/>
  </inertial>
  <visual>
    <origin rpy="0 0 0" xyz="-0.180842 0.15813 0.150054"/>
    <geometry>
      <mesh filename="package://ayspot_a1_description/meshes/RF_SHANK_1.stl" scale="0.001 0.001 0.001"/>
    </geometry>
    <material name="silver"/>
  </visual>
  <collision>
    <origin rpy="0 0 0" xyz="-0.180842 0.15813 0.150054"/>
    <geometry>
      <mesh filename="package://ayspot_a1_description/meshes/RF_SHANK_1.stl" scale="0.001 0.001 0.001"/>
    </geometry>
  </collision>
</link>

<link name="RF_FOOT_1">
  <inertial>
    <origin rpy="0 0 0" xyz="-0.0002334102178116193 2.4482443017337374e-09 -0.000901072853188245"/>
    <mass value="0.033833533910103936"/>
    <inertia ixx="6e-06" ixy="-0.0" ixz="0.0" iyy="6e-06" iyz="0.0" izz="6e-06"/>
  </inertial>
  <visual>
    <origin rpy="0 0 0" xyz="-0.180859 0.15813 0.330081"/>
    <geometry>
      <mesh filename="package://ayspot_a1_description/meshes/RF_FOOT_1.stl" scale="0.001 0.001 0.001"/>
    </geometry>
    <material name="silver"/>
  </visual>
  <collision>
    <origin rpy="0 0 0" xyz="-0.180859 0.15813 0.330081"/>
    <geometry>
      <mesh filename="package://ayspot_a1_description/meshes/RF_FOOT_1.stl" scale="0.001 0.001 0.001"/>
    </geometry>
  </collision>
</link>

<link name="LF_HIP_1">
  <inertial>
    <origin rpy="0 0 0" xyz="-0.023084407355488973 0.00678286308672349 5.572806059883177e-08"/>
    <mass value="1.4355159810982792"/>
    <inertia ixx="0.001763" ixy="-4.2e-05" ixz="0.0" iyy="0.002514" iyz="0.0" izz="0.001514"/>
  </inertial>
  <visual>
    <origin rpy="0 0 0" xyz="-0.1808 -0.065 0.0"/>
    <geometry>
      <mesh filename="package://ayspot_a1_description/meshes/LF_HIP_1.stl" scale="0.001 0.001 0.001"/>
    </geometry>
    <material name="silver"/>
  </visual>
  <collision>
    <origin rpy="0 0 0" xyz="-0.1808 -0.065 0.0"/>
    <geometry>
      <mesh filename="package://ayspot_a1_description/meshes/LF_HIP_1.stl" scale="0.001 0.001 0.001"/>
    </geometry>
  </collision>
</link>

<link name="LF_THIGH_1">
  <inertial>
    <origin rpy="0 0 0" xyz="3.152076878396026e-05 -0.029669373982814884 -0.0140945333441053"/>
    <mass value="1.9354245387114206"/>
    <inertia ixx="0.005386" ixy="-2e-06" ixz="2e-06" iyy="0.005003" iyz="0.000911" izz="0.002334"/>
  </inertial>
  <visual>
    <origin rpy="0 0 0" xyz="-0.1808 -0.1588 -0.0"/>
    <geometry>
      <mesh filename="package://ayspot_a1_description/meshes/LF_THIGH_1.stl" scale="0.001 0.001 0.001"/>
    </geometry>
    <material name="silver"/>
  </visual>
  <collision>
    <origin rpy="0 0 0" xyz="-0.1808 -0.1588 -0.0"/>
    <geometry>
      <mesh filename="package://ayspot_a1_description/meshes/LF_THIGH_1.stl" scale="0.001 0.001 0.001"/>
    </geometry>
  </collision>
</link>

<link name="LF_SHANK_1">
  <inertial>
    <origin rpy="0 0 0" xyz="0.0063163530647590005 -2.225074113015868e-07 -0.06808977329393792"/>
    <mass value="0.5487464783038492"/>
    <inertia ixx="0.002626" ixy="-0.0" ixz="3.2e-05" iyy="0.002673" iyz="0.0" izz="9.8e-05"/>
  </inertial>
  <visual>
    <origin rpy="0 0 0" xyz="-0.180758 -0.15813 0.150054"/>
    <geometry>
      <mesh filename="package://ayspot_a1_description/meshes/LF_SHANK_1.stl" scale="0.001 0.001 0.001"/>
    </geometry>
    <material name="silver"/>
  </visual>
  <collision>
    <origin rpy="0 0 0" xyz="-0.180758 -0.15813 0.150054"/>
    <geometry>
      <mesh filename="package://ayspot_a1_description/meshes/LF_SHANK_1.stl" scale="0.001 0.001 0.001"/>
    </geometry>
  </collision>
</link>

<link name="LF_FOOT_1">
  <inertial>
    <origin rpy="0 0 0" xyz="-0.0002332855469918682 2.448246216868455e-09 -0.000901072853188245"/>
    <mass value="0.033833533910103936"/>
    <inertia ixx="6e-06" ixy="-0.0" ixz="0.0" iyy="6e-06" iyz="0.0" izz="6e-06"/>
  </inertial>
  <visual>
    <origin rpy="0 0 0" xyz="-0.180775 -0.15813 0.330081"/>
    <geometry>
      <mesh filename="package://ayspot_a1_description/meshes/LF_FOOT_1.stl" scale="0.001 0.001 0.001"/>
    </geometry>
    <material name="silver"/>
  </visual>
  <collision>
    <origin rpy="0 0 0" xyz="-0.180775 -0.15813 0.330081"/>
    <geometry>
      <mesh filename="package://ayspot_a1_description/meshes/LF_FOOT_1.stl" scale="0.001 0.001 0.001"/>
    </geometry>
  </collision>
</link>

<link name="RH_HIP_1">
  <inertial>
    <origin rpy="0 0 0" xyz="0.023084407355489972 -0.0067828630867233924 5.572806059883164e-08"/>
    <mass value="1.435515981098277"/>
    <inertia ixx="0.001763" ixy="-4.2e-05" ixz="-0.0" iyy="0.002514" iyz="-0.0" izz="0.001514"/>
  </inertial>
  <visual>
    <origin rpy="0 0 0" xyz="0.1808 0.065 0.0"/>
    <geometry>
      <mesh filename="package://ayspot_a1_description/meshes/RH_HIP_1.stl" scale="0.001 0.001 0.001"/>
    </geometry>
    <material name="silver"/>
  </visual>
  <collision>
    <origin rpy="0 0 0" xyz="0.1808 0.065 0.0"/>
    <geometry>
      <mesh filename="package://ayspot_a1_description/meshes/RH_HIP_1.stl" scale="0.001 0.001 0.001"/>
    </geometry>
  </collision>
</link>

<link name="RH_THIGH_1">
  <inertial>
    <origin rpy="0 0 0" xyz="-3.152076878404353e-05 0.02966937398281505 -0.014094533344105344"/>
    <mass value="1.9354245387114226"/>
    <inertia ixx="0.005386" ixy="-2e-06" ixz="-2e-06" iyy="0.005003" iyz="-0.000911" izz="0.002334"/>
  </inertial>
  <visual>
    <origin rpy="0 0 0" xyz="0.1808 0.1588 -0.0"/>
    <geometry>
      <mesh filename="package://ayspot_a1_description/meshes/RH_THIGH_1.stl" scale="0.001 0.001 0.001"/>
    </geometry>
    <material name="silver"/>
  </visual>
  <collision>
    <origin rpy="0 0 0" xyz="0.1808 0.1588 -0.0"/>
    <geometry>
      <mesh filename="package://ayspot_a1_description/meshes/RH_THIGH_1.stl" scale="0.001 0.001 0.001"/>
    </geometry>
  </collision>
</link>

<link name="RH_SHANK_1">
  <inertial>
    <origin rpy="0 0 0" xyz="0.006316228393691309 -2.225060020399905e-07 -0.06808977329384336"/>
    <mass value="0.5487464783038579"/>
    <inertia ixx="0.002626" ixy="-0.0" ixz="3.2e-05" iyy="0.002673" iyz="0.0" izz="9.8e-05"/>
  </inertial>
  <visual>
    <origin rpy="0 0 0" xyz="0.180758 0.15813 0.150054"/>
    <geometry>
      <mesh filename="package://ayspot_a1_description/meshes/RH_SHANK_1.stl" scale="0.001 0.001 0.001"/>
    </geometry>
    <material name="silver"/>
  </visual>
  <collision>
    <origin rpy="0 0 0" xyz="0.180758 0.15813 0.150054"/>
    <geometry>
      <mesh filename="package://ayspot_a1_description/meshes/RH_SHANK_1.stl" scale="0.001 0.001 0.001"/>
    </geometry>
  </collision>
</link>

<link name="RH_FOOT_1">
  <inertial>
    <origin rpy="0 0 0" xyz="-0.00023341021781145277 2.4482443850004643e-09 -0.0009010728531874679"/>
    <mass value="0.033833533910103936"/>
    <inertia ixx="6e-06" ixy="-0.0" ixz="0.0" iyy="6e-06" iyz="0.0" izz="6e-06"/>
  </inertial>
  <visual>
    <origin rpy="0 0 0" xyz="0.180741 0.15813 0.330081"/>
    <geometry>
      <mesh filename="package://ayspot_a1_description/meshes/RH_FOOT_1.stl" scale="0.001 0.001 0.001"/>
    </geometry>
    <material name="silver"/>
  </visual>
  <collision>
    <origin rpy="0 0 0" xyz="0.180741 0.15813 0.330081"/>
    <geometry>
      <mesh filename="package://ayspot_a1_description/meshes/RH_FOOT_1.stl" scale="0.001 0.001 0.001"/>
    </geometry>
  </collision>
</link>

<link name="LH_HIP_1">
  <inertial>
    <origin rpy="0 0 0" xyz="0.023084404729864005 0.00678286243481846 -5.5748818857752784e-08"/>
    <mass value="1.4355160412440464"/>
    <inertia ixx="0.001763" ixy="4.2e-05" ixz="0.0" iyy="0.002514" iyz="-0.0" izz="0.001514"/>
  </inertial>
  <visual>
    <origin rpy="0 0 0" xyz="0.1808 -0.065 0.0"/>
    <geometry>
      <mesh filename="package://ayspot_a1_description/meshes/LH_HIP_1.stl" scale="0.001 0.001 0.001"/>
    </geometry>
    <material name="silver"/>
  </visual>
  <collision>
    <origin rpy="0 0 0" xyz="0.1808 -0.065 0.0"/>
    <geometry>
      <mesh filename="package://ayspot_a1_description/meshes/LH_HIP_1.stl" scale="0.001 0.001 0.001"/>
    </geometry>
  </collision>
</link>

<link name="LH_THIGH_1">
  <inertial>
    <origin rpy="0 0 0" xyz="3.152076878390475e-05 -0.029669373982814884 -0.014094533344105618"/>
    <mass value="1.9354245387114206"/>
    <inertia ixx="0.005386" ixy="-2e-06" ixz="2e-06" iyy="0.005003" iyz="0.000911" izz="0.002334"/>
  </inertial>
  <visual>
    <origin rpy="0 0 0" xyz="0.1808 -0.1588 0.0"/>
    <geometry>
      <mesh filename="package://ayspot_a1_description/meshes/LH_THIGH_1.stl" scale="0.001 0.001 0.001"/>
    </geometry>
    <material name="silver"/>
  </visual>
  <collision>
    <origin rpy="0 0 0" xyz="0.1808 -0.1588 0.0"/>
    <geometry>
      <mesh filename="package://ayspot_a1_description/meshes/LH_THIGH_1.stl" scale="0.001 0.001 0.001"/>
    </geometry>
  </collision>
</link>

<link name="LH_SHANK_1">
  <inertial>
    <origin rpy="0 0 0" xyz="0.006316353064758973 -2.2250741135709795e-07 -0.06808977329393828"/>
    <mass value="0.5487464783038492"/>
    <inertia ixx="0.002626" ixy="-0.0" ixz="3.2e-05" iyy="0.002673" iyz="0.0" izz="9.8e-05"/>
  </inertial>
  <visual>
    <origin rpy="0 0 0" xyz="0.180842 -0.15813 0.150054"/>
    <geometry>
      <mesh filename="package://ayspot_a1_description/meshes/LH_SHANK_1.stl" scale="0.001 0.001 0.001"/>
    </geometry>
    <material name="silver"/>
  </visual>
  <collision>
    <origin rpy="0 0 0" xyz="0.180842 -0.15813 0.150054"/>
    <geometry>
      <mesh filename="package://ayspot_a1_description/meshes/LH_SHANK_1.stl" scale="0.001 0.001 0.001"/>
    </geometry>
  </collision>
</link>

<link name="LH_FOOT_1">
  <inertial>
    <origin rpy="0 0 0" xyz="-0.00023328554699189596 2.448246216868455e-09 -0.0009010728531885781"/>
    <mass value="0.033833533910103936"/>
    <inertia ixx="6e-06" ixy="-0.0" ixz="0.0" iyy="6e-06" iyz="0.0" izz="6e-06"/>
  </inertial>
  <visual>
    <origin rpy="0 0 0" xyz="0.180825 -0.15813 0.330081"/>
    <geometry>
      <mesh filename="package://ayspot_a1_description/meshes/LH_FOOT_1.stl" scale="0.001 0.001 0.001"/>
    </geometry>
    <material name="silver"/>
  </visual>
  <collision>
    <origin rpy="0 0 0" xyz="0.180825 -0.15813 0.330081"/>
    <geometry>
      <mesh filename="package://ayspot_a1_description/meshes/LH_FOOT_1.stl" scale="0.001 0.001 0.001"/>
    </geometry>
  </collision>
</link>

<joint name="RF_HIP_rotate" type="continuous">
  <origin rpy="0 0 0" xyz="0.1808 -0.065 0.0"/>
  <parent link="base_link"/>
  <child link="RF_HIP_1"/>
  <axis xyz="1.0 0.0 0.0"/>
</joint>

<joint name="RF_THIGH_rotate" type="continuous">
  <origin rpy="0 0 0" xyz="0.0 -0.0938 0.0"/>
  <parent link="RF_HIP_1"/>
  <child link="RF_THIGH_1"/>
  <axis xyz="0.0 1.0 0.0"/>
</joint>

<joint name="RF_SHANK_rotate" type="continuous">
  <origin rpy="0 0 0" xyz="4.2e-05 0.00067 -0.150054"/>
  <parent link="RF_THIGH_1"/>
  <child link="RF_SHANK_1"/>
  <axis xyz="0.0 1.0 -0.0"/>
</joint>

<joint name="RF_FOOT_rigid" type="fixed">
  <origin rpy="0 0 0" xyz="1.7e-05 0.0 -0.180027"/>
  <parent link="RF_SHANK_1"/>
  <child link="RF_FOOT_1"/>
</joint>

<joint name="LF_HIP_rotate" type="continuous">
  <origin rpy="0 0 0" xyz="0.1808 0.065 0.0"/>
  <parent link="base_link"/>
  <child link="LF_HIP_1"/>
  <axis xyz="1.0 0.0 0.0"/>
</joint>

<joint name="LF_THIGH_rotate" type="continuous">
  <origin rpy="0 0 0" xyz="0.0 0.0938 0.0"/>
  <parent link="LF_HIP_1"/>
  <child link="LF_THIGH_1"/>
  <axis xyz="0.0 1.0 0.0"/>
</joint>

<joint name="LF_SHANK_rotate" type="continuous">
  <origin rpy="0 0 0" xyz="-4.2e-05 -0.00067 -0.150054"/>
  <parent link="LF_THIGH_1"/>
  <child link="LF_SHANK_1"/>
  <axis xyz="0.0 1.0 0.0"/>
</joint>

<joint name="LF_FOOT_rigid" type="fixed">
  <origin rpy="0 0 0" xyz="1.7e-05 0.0 -0.180027"/>
  <parent link="LF_SHANK_1"/>
  <child link="LF_FOOT_1"/>
</joint>

<joint name="RH_HIP_rotate" type="continuous">
  <origin rpy="0 0 0" xyz="-0.1808 -0.065 0.0"/>
  <parent link="base_link"/>
  <child link="RH_HIP_1"/>
  <axis xyz="1.0 0.0 0.0"/>
</joint>

<joint name="RH_THIGH_rotate" type="continuous">
  <origin rpy="0 0 0" xyz="0.0 -0.0938 0.0"/>
  <parent link="RH_HIP_1"/>
  <child link="RH_THIGH_1"/>
  <axis xyz="0.0 1.0 -0.0"/>
</joint>

<joint name="RH_SHANK_rotate" type="continuous">
  <origin rpy="0 0 0" xyz="4.2e-05 0.00067 -0.150054"/>
  <parent link="RH_THIGH_1"/>
  <child link="RH_SHANK_1"/>
  <axis xyz="0.0 1.0 -0.0"/>
</joint>

<joint name="RH_FOOT_rigid" type="fixed">
  <origin rpy="0 0 0" xyz="1.7e-05 0.0 -0.180027"/>
  <parent link="RH_SHANK_1"/>
  <child link="RH_FOOT_1"/>
</joint>

<joint name="LH_HIP_rotate" type="continuous">
  <origin rpy="0 0 0" xyz="-0.1808 0.065 0.0"/>
  <parent link="base_link"/>
  <child link="LH_HIP_1"/>
  <axis xyz="1.0 0.0 0.0"/>
</joint>

<joint name="LH_THIGH_rotate" type="continuous">
  <origin rpy="0 0 0" xyz="0.0 0.0938 0.0"/>
  <parent link="LH_HIP_1"/>
  <child link="LH_THIGH_1"/>
  <axis xyz="-0.0 1.0 -0.0"/>
</joint>

<joint name="LH_SHANK_rotate" type="continuous">
  <origin rpy="0 0 0" xyz="-4.2e-05 -0.00067 -0.150054"/>
  <parent link="LH_THIGH_1"/>
  <child link="LH_SHANK_1"/>
  <axis xyz="0.0 1.0 -0.0"/>
</joint>

<joint name="LH_FOOT_rigid" type="fixed">
  <origin rpy="0 0 0" xyz="1.7e-05 0.0 -0.180027"/>
  <parent link="LH_SHANK_1"/>
  <child link="LH_FOOT_1"/>
</joint>

</robot>
